<?xml version="1.0" encoding="utf-8"?>
<!-- This URDF was automatically created by SolidWorks to URDF Exporter! Originally created by Stephen Brawner (brawner@gmail.com) 
     Commit Version: 1.6.0-4-g7f85cfe  Build Version: 1.6.7995.38578
     For more information, please see http://wiki.ros.org/sw_urdf_exporter -->
<robot
  name="serpent">
  
     <gazebo>
    <plugin name="gazebo_ros_control" filename="libgazebo_ros_control.so">
      <robotNamespace>/serpent_gazebo</robotNamespace>
    </plugin>
  </gazebo>
 
   
  <transmission name="serpent_joint_1_trans">
    <type>transmission_interface/SimpleTransmission</type>
    <actuator name="motor1">
      <mechanicalReduction>1</mechanicalReduction>
    </actuator>
    <joint name="serpent_joint_1">
      <hardwareInterface>hardware_interface/EffortJointInterface</hardwareInterface>
    </joint>
  </transmission> 
  
  
  <link name="world" />
  
  <joint name="dummy_link" type="fixed">
    <parent link="world"/>
    <child link="BOTTOM"/>
  </joint>
  
  <link
    name="BOTTOM">
    <inertial>
      <origin
        xyz="-0.00313734991230859 -0.00474622649736089 0.0419505748550408"
        rpy="0 0 0" />
      <mass
        value="0.248846427803799" />
      <inertia
        ixx="0.000337065099453283"
        ixy="-7.04565952367779E-07"
        ixz="4.81639331367407E-06"
        iyy="0.00043528469589621"
        iyz="-8.21355335871629E-06"
        izz="0.000319081784729365" />
    </inertial>
    <visual>
      <origin
        xyz="0 0 0"
        rpy="0 0 0" />
      <geometry>
        <mesh
          filename="package://serpent_gazebo/meshes/BOTTOM.STL" />
      </geometry>
      <material
        name="">
        <color
          rgba="0.792156862745098 0.819607843137255 0.933333333333333 1" />
      </material>
    </visual>
    <collision>
      <origin
        xyz="0 0 0"
        rpy="0 0 0" />
      <geometry>
        <mesh
          filename="package://serpent_gazebo/meshes/BOTTOM.STL" />
      </geometry>
    </collision>
  </link>
  -->
  <link
    name="TOP">
    <inertial>
      <origin
        xyz="0.00351440727191355 -0.112572278209649 -0.000478766564033797"
        rpy="0 0 0" />
      <mass
        value="0.503745908624564" />
      <inertia
        ixx="0.00216516689167981"
        ixy="-2.7241873369572E-06"
        ixz="5.1400856991087E-06"
        iyy="0.000889853519288545"
        iyz="-1.73937977239561E-05"
        izz="0.00219647789821076" />
    </inertial>
    <visual>
      <origin
        xyz="0 0 0"
        rpy="0 0 0" />
      <geometry>
        <mesh
          filename="package://serpent_gazebo/meshes/TOP.STL" />
      </geometry>
      <material
        name="">
        <color
          rgba="0.792156862745098 0.819607843137255 0.933333333333333 1" />
      </material>
    </visual>
    <collision>
      <origin
        xyz="0 0 0"
        rpy="0 0 0" />
      <geometry>
        <mesh
          filename="package://serpent_gazebo/meshes/TOP.STL" />
      </geometry>
    </collision>
  </link>
  
  <joint
    name="serpent_joint_1"
    type="continuous">
    <origin
      xyz="0 -0.044432012931505 -0.0505772211610462"
      rpy="1.31422119136425 0 -3.14159265358979" />
    <parent
      link="BOTTOM" />
    <child
      link="TOP" />
    <axis
      xyz="1 0 0" />
  </joint>
  
</robot>
